ERROR:    Exception in ASGI application
Traceback (most recent call last):
  File "/home/smdydx/Downloads/LCRAdmin/project/backend/venv/lib/python3.12/site-packages/uvicorn/protocols/http/httptools_impl.py", line 409, in run_asgi
    result = await app(  # type: ignore[func-returns-value]
             ^^^^^^^^^^^^^^^^^^^^^^^^^^^^^^^^^^^^^^^^^^^^^^
  File "/home/smdydx/Downloads/LCRAdmin/project/backend/venv/lib/python3.12/site-packages/uvicorn/middleware/proxy_headers.py", line 60, in __call__
    return await self.app(scope, receive, send)
           ^^^^^^^^^^^^^^^^^^^^^^^^^^^^^^^^^^^^
  File "/home/smdydx/Downloads/LCRAdmin/project/backend/venv/lib/python3.12/site-packages/fastapi/applications.py", line 1133, in __call__
    await super().__call__(scope, receive, send)
  File "/home/smdydx/Downloads/LCRAdmin/project/backend/venv/lib/python3.12/site-packages/starlette/applications.py", line 113, in __call__
    await self.middleware_stack(scope, receive, send)
  File "/home/smdydx/Downloads/LCRAdmin/project/backend/venv/lib/python3.12/site-packages/starlette/middleware/errors.py", line 186, in __call__
    raise exc
  File "/home/smdydx/Downloads/LCRAdmin/project/backend/venv/lib/python3.12/site-packages/starlette/middleware/errors.py", line 164, in __call__
    await self.app(scope, receive, _send)
  File "/home/smdydx/Downloads/LCRAdmin/project/backend/venv/lib/python3.12/site-packages/starlette/middleware/cors.py", line 85, in __call__
    await self.app(scope, receive, send)
  File "/home/smdydx/Downloads/LCRAdmin/project/backend/venv/lib/python3.12/site-packages/starlette/middleware/exceptions.py", line 63, in __call__
    await wrap_app_handling_exceptions(self.app, conn)(scope, receive, send)
  File "/home/smdydx/Downloads/LCRAdmin/project/backend/venv/lib/python3.12/site-packages/starlette/_exception_handler.py", line 53, in wrapped_app
    raise exc
  File "/home/smdydx/Downloads/LCRAdmin/project/backend/venv/lib/python3.12/site-packages/starlette/_exception_handler.py", line 42, in wrapped_app
    await app(scope, receive, sender)
  File "/home/smdydx/Downloads/LCRAdmin/project/backend/venv/lib/python3.12/site-packages/fastapi/middleware/asyncexitstack.py", line 18, in __call__
    await self.app(scope, receive, send)
  File "/home/smdydx/Downloads/LCRAdmin/project/backend/venv/lib/python3.12/site-packages/starlette/routing.py", line 716, in __call__
    await self.middleware_stack(scope, receive, send)
  File "/home/smdydx/Downloads/LCRAdmin/project/backend/venv/lib/python3.12/site-packages/starlette/routing.py", line 736, in app
    await route.handle(scope, receive, send)
  File "/home/smdydx/Downloads/LCRAdmin/project/backend/venv/lib/python3.12/site-packages/starlette/routing.py", line 290, in handle
    await self.app(scope, receive, send)
  File "/home/smdydx/Downloads/LCRAdmin/project/backend/venv/lib/python3.12/site-packages/fastapi/routing.py", line 123, in app
    await wrap_app_handling_exceptions(app, request)(scope, receive, send)
  File "/home/smdydx/Downloads/LCRAdmin/project/backend/venv/lib/python3.12/site-packages/starlette/_exception_handler.py", line 53, in wrapped_app
    raise exc
  File "/home/smdydx/Downloads/LCRAdmin/project/backend/venv/lib/python3.12/site-packages/starlette/_exception_handler.py", line 42, in wrapped_app
    await app(scope, receive, sender)
  File "/home/smdydx/Downloads/LCRAdmin/project/backend/venv/lib/python3.12/site-packages/fastapi/routing.py", line 109, in app
    response = await f(request)
               ^^^^^^^^^^^^^^^^
  File "/home/smdydx/Downloads/LCRAdmin/project/backend/venv/lib/python3.12/site-packages/fastapi/routing.py", line 411, in app
    content = await serialize_response(
              ^^^^^^^^^^^^^^^^^^^^^^^^^
  File "/home/smdydx/Downloads/LCRAdmin/project/backend/venv/lib/python3.12/site-packages/fastapi/routing.py", line 252, in serialize_response
    raise ResponseValidationError(
fastapi.exceptions.ResponseValidationError: 60 validation errors: